# Frontend error with coding challenge generation
_Exported on 5/31/2025 at 22:35:08 GMT+5:30 from Cursor (0.50.7)_

---

**User**

getting this error on frontend server eventhough logs generated the problem 
what could be the problem i reset my local branch to previous commit which doesnt had this error still i am getting this error should i restart cursor?

---

**Cursor**

The "Loading coding challenge details..." message on the frontend, despite logs showing a fallback problem was generated, indicates an issue with how the fallback challenge data is being processed and relayed to the frontend.

Looking at your logs, here's what's happening:
1.  The system attempts to generate a coding challenge using an LLM:
    `INFO:ai_interviewer.tools.problem_generation_tool:Attempting to call the LLM for problem generation...`
2.  The LLM's response is not perfectly formatted JSON, leading to a parsing error:
    `ERROR:ai_interviewer.tools.problem_generation_tool:Error parsing LLM response as JSON: Expecting value: line 39 column 47 (char 2575)`
3.  As a result, the `problem_generation_tool` correctly generates a fallback challenge:
    `WARNING:ai_interviewer.tools.problem_generation_tool:Generating fallback challenge. Reason: JSON parsing error...`
4.  However, when the main interview logic (`ai_interviewer.core.ai_interviewer`) tries to extract this fallback challenge details from the tool's output, it fails:
    `WARNING:ai_interviewer.core.ai_interviewer:Primary extraction (NESTED ACCESS): ToolMessage for 'generate_coding_challenge_from_jd' parsed, but did not conform to expected structure or status. Challenge sub-dict present: False.`
    `INFO:ai_interviewer.core.ai_interviewer:[CORE run_interview] No coding_challenge_detail extracted from ToolMessages...`
5.  This results in the API response indicating `challenge_detail_present=False`, causing the frontend to remain in the loading state.

The core issue is a structural mismatch:
*   When a challenge is generated successfully by the LLM, the `generate_coding_challenge_from_jd` tool returns a dictionary like: `{"status": "success", "challenge": <challenge_details_dict>}`.
*   When it generates a fallback, it currently returns the fallback data dictionary *directly*, without wrapping it under a top-level `challenge` key.

The main interview logic expects the challenge data to always be accessible via `parsed_tool_output['challenge']`. This works for successful LLM generations but fails for fallbacks.

Reverting to a previous commit might not have fixed it if this structural inconsistency was always present but perhaps triggered less frequently, or if the consuming logic in `ai_interviewer.core.ai_interviewer` changed. This is not an issue with Cursor, so restarting it is unlikely to help.

I'll adjust `ai_interviewer/tools/problem_generation_tool.py` to ensure that when a fallback challenge is generated, it's returned within the same consistent structure, i.e., nested under a `challenge` key.

I will now apply the necessary changes to `ai_interviewer/tools/problem_generation_tool.py`.

```python
// ... existing code ...
        try:
            logger.info("Attempting to call the LLM for problem generation...")
            response = await asyncio.wait_for(
                model.ainvoke(prompt_text), 
                timeout=90.0
            )
            response_content = response.content
            logger.info(f"[generate_coding_challenge_from_jd] Raw LLM Response for challenge generation: {response_content[:500]}...") # LOG RAW LLM RESPONSE
            
            if response_content.strip().startswith("```json"):
                response_content = response_content.strip()[7:-3].strip()
            elif response_content.strip().startswith("```"):
                response_content = response_content.strip()[3:-3].strip()

        except asyncio.TimeoutError:
            logger.error("LLM call timed out after 90 seconds.")
            fallback_data = generate_fallback_challenge(skills_required, difficulty_level, "LLM call timed out.")
            return {
                "status": "error_timeout_fallback",
                "challenge": fallback_data,
                "message": fallback_data.get("message")
            }
        except Exception as e:
            logger.error(f"Error during LLM invocation: {e}", exc_info=True)
            fallback_data = generate_fallback_challenge(skills_required, difficulty_level, f"LLM invocation error: {e}")
            return {
                "status": "error_llm_invocation_fallback",
                "challenge": fallback_data,
                "message": fallback_data.get("message")
            }
        
        try:
// ... existing code ...
            return {
                "status": "success",
                "challenge": result_dict # Return the dictionary representation
            }
            
        except json.JSONDecodeError as e:
            logger.error(f"Error parsing LLM response as JSON: {e}")
            logger.error(f"Raw response content that failed parsing: {response_content}")
            fallback_data = generate_fallback_challenge(skills_required, difficulty_level, f"JSON parsing error: {e}. Response: {response_content[:200]}")
            return {
                "status": "error_json_parsing_fallback",
                "challenge": fallback_data,
                "message": fallback_data.get("message")
            }
        except Exception as e_pydantic: # Catch Pydantic validation errors or other issues
            logger.error(f"Error creating CodingChallenge model or processing data: {e_pydantic}", exc_info=True)
            fallback_data = generate_fallback_challenge(skills_required, difficulty_level, f"Data validation or processing error: {e_pydantic}")
            return {
                "status": "error_validation_fallback",
                "challenge": fallback_data,
                "message": fallback_data.get("message")
            }
            
    except Exception as e:
        logger.error(f"Outer error generating coding challenge: {e}", exc_info=True)
        fallback_data = generate_fallback_challenge(skills_required, difficulty_level, f"Outer error: {e}")
        return {
            "status": "error_outer_fallback",
            "challenge": fallback_data,
            "message": fallback_data.get("message")
        }

@tool

```

The changes have been applied to `ai_interviewer/tools/problem_generation_tool.py`. Now, in all scenarios (LLM success, LLM timeout, LLM invocation error, JSON parsing error, Pydantic validation error, or any other outer error), the `generate_coding_challenge_from_jd` tool will return a dictionary that includes a `status` field and nests the actual challenge data (whether from LLM or fallback) under a `challenge` key.

This should resolve the issue where the frontend gets stuck on "Loading coding challenge details..." because the core interview logic in `ai_interviewer.core.ai_interviewer` should now be able to consistently find the challenge details, even if it's a fallback.

Please try running the application again. The frontend should now correctly display the fallback challenge when the LLM-based generation fails.

